Workbook

Sheet Read_Me
A1: Pulse Diagnostics Senior & Leadership Attrition Analysis | D1: Amy Bushell, Leticia Mie Otani, Luke (Tak Lung) Chan - Group #3 | K1: 46082
A3: This workbook contains the data analysis for our Pulse Diagnostics Senior & Leadership Attrition Analysis project. The purpose is to test the top 10 prioritized hypotheses related to attrition risk among senior and leadership employees. This aligns with the project objective of identifying where attrition risk is concentrated and what factors may be driving it.
A5: Tabs in the Excel Spreadsheet
A6: Read_Me | B6: Current Tab
A7: Clean_data | B7: Final cleaned, combined and enriched analysis dataset
A8: H1 - H10 | B8: Hypothesis testing
A9: External Data | B9: Supporting external benchmark data information
A10: Employee Engagement Survey | B10: Survey scoring
A11: Data Dictionary | B11: Column Header Definitions
A12: Summary Findings | B12: conclusion of 10 hypothesis testing
A15: Calculated Fields
A16: Attrition Flag | B16: 1=exited, 0=active
A17: Senior Leadership Filter | B17: 1=Leadership Role (Managers, Research Director, Manufacturing Director), 0=Non
A18: Tenure Stage Groupings | B18: Early tenure (<2 yrs), Mid tenure (3–9 yrs), Long tenure (10+ yrs)
A19: Overall (Avg) Employee Engagement Survey Score | B19: Calculated average of 4 engagement survey questions (scale 1-4)
A20: Recent Exit Flag | B20: 1=Recent Exits within 2024 or 2025, 0=Active or not recent exit
A22: Exit Date | B22: Additonal Data Received
A23: Exit Type | B23: Additonal Data Received
A26: Statistical Techniques Used In this workbook:
A27: Descriptive statistics (pivot tables and averages)
A28: attrition rate calculations
A29: chi-square comparisons
A30: t-tests
A31: correlation analysis
A34: Some fields of data not being used in analysis have been hidden.

Sheet Clean_Data
A1: EmployeeNumber | B1: Active Employee? | C1: Attrition Flag | D1: JobRole | E1: Senior Leadership Filter | F1: Department | G1: JobLevel | H1: AnnualCompensation | I1: PercentSalaryHike | J1: Weekly StandardHours | K1: OverTime Eligible | L1: Age | M1: GenderIdentity | N1: MaritalStatus | O1: BusinessTravel | P1: DistanceFromHome (kms) | Q1: Education Level | R1: EducationField | S1: PerformanceRating | T1: StockOptionLevel | U1: Years of Work Experience | V1: TrainingTimesLastYear | W1: Tenure | X1: YearsInCurrentRole | Y1: YearsSinceLastPromotion | Z1: YearsWithCurrManager | AA1: Tenure Stage | AB1: Exit Date | AC1: Recent Exit Flag | AD1: Exit Type | AE1: WorkEnvironmentSatisfaction | AF1: JobSatisfaction | AG1: Manager Satisfaction | AH1: WorkLifeBalance Score | AI1: Overall Engagement Score
A2: 701 | B2: Yes | C2: =IF(B2="No",1,0) -> 0 | D2: Research Scientist | E2: =IF(OR(D2="Manager, HR", D2="Manager, Sales", D2="Manager, R&D", D2="Manufacturing Director",D2="Research Director", D2="VP, HR", D2="CEO"),1,0) -> 0 | F2: Research & Development | G2: 1 | H2: 36108 | I2: 0.11 | J2: 37.5 | K2: Yes | L2: 20 | M2: Man | N2: Single | O2: Travel_Rarely | P2: 10 | Q2: Trades Apprenticeship | R2: Medical | S2: 3 | T2: 0 | U2: 1 | V2: 5 | W2: 1 | X2: 0 | Y2: 1 | Z2: 1 | AA2: =IF(W2<=2,"Early Tenure",IF(W2<=9,"Mid Tenure","Long Tenure")) -> Early Tenure | AC2: =IF(AND(AB2<>"",AB2>DATE(2024,1,1)),1,0) -> 0 | AE2: =VLOOKUP(A2,'Employee Engagement Survey'!A2:B1471,2,FALSE) -> 4 | AF2: =VLOOKUP(A2,'Employee Engagement Survey'!A2:C1471,3,FALSE) -> 3 | AG2: =VLOOKUP(A2,'Employee Engagement Survey'!A2:D1471,4,FALSE) -> 4 | AH2: =VLOOKUP(A2,'Employee Engagement Survey'!A2:E1471,5,FALSE) -> 3 | AI2: =AVERAGE(AE2:AH2) -> 3.5
A3: 1876 | B3: Yes | C3: =IF(B3="No",1,0) -> 0 | D3: Sales Representative | E3: =IF(OR(D3="Manager, HR", D3="Manager, Sales", D3="Manager, R&D", D3="Manufacturing Director",D3="Research Director", D3="VP, HR", D3="CEO"),1,0) -> 0 | F3: Sales | G3: 1 | H3: 36972 | I3: 0.13 | J3: 37.5 | K3: No | L3: 30 | M3: Man | N3: Single | O3: Travel_Rarely | P3: 9 | Q3: Bachelor's Degree | R3: Medical | S3: 3 | T3: 0 | U3: 1 | V3: 3 | W3: 1 | X3: 0 | Y3: 0 | Z3: 0 | AA3: =IF(W3<=2,"Early Tenure",IF(W3<=9,"Mid Tenure","Long Tenure")) -> Early Tenure | AC3: =IF(AND(AB3<>"",AB3>DATE(2024,1,1)),1,0) -> 0 | AE3: =VLOOKUP(A3,'Employee Engagement Survey'!A5:B1474,2,FALSE) -> 2 | AF3: =VLOOKUP(A3,'Employee Engagement Survey'!A5:C1474,3,FALSE) -> 4 | AG3: =VLOOKUP(A3,'Employee Engagement Survey'!A5:D1474,4,FALSE) -> 3 | AH3: =VLOOKUP(A3,'Employee Engagement Survey'!A5:E1474,5,FALSE) -> 2 | AI3: =AVERAGE(AE3:AH3) -> 2.75
A4: 1928 | B4: Yes | C4: =IF(B4="No",1,0) -> 0 | D4: Sales Representative | E4: =IF(OR(D4="Manager, HR", D4="Manager, Sales", D4="Manager, R&D", D4="Manufacturing Director",D4="Research Director", D4="VP, HR", D4="CEO"),1,0) -> 0 | F4: Sales | G4: 1 | H4: 37092 | I4: 0.17 | J4: 37.5 | K4: No | L4: 29 | M4: Man | N4: Single | O4: Travel_Frequently | P4: 24 | Q4: Bachelor's Degree | R4: Technical Degree | S4: 3 | T4: 0 | U4: 1 | V4: 3 | W4: 1 | X4: 0 | Y4: 0 | Z4: 0 | AA4: =IF(W4<=2,"Early Tenure",IF(W4<=9,"Mid Tenure","Long Tenure")) -> Early Tenure | AC4: =IF(AND(AB4<>"",AB4>DATE(2024,1,1)),1,0) -> 0 | AE4: =VLOOKUP(A4,'Employee Engagement Survey'!A6:B1475,2,FALSE) -> 3 | AF4: =VLOOKUP(A4,'Employee Engagement Survey'!A6:C1475,3,FALSE) -> 1 | AG4: =VLOOKUP(A4,'Employee Engagement Survey'!A6:D1475,4,FALSE) -> 4 | AH4: =VLOOKUP(A4,'Employee Engagement Survey'!A6:E1475,5,FALSE) -> 3 | AI4: =AVERAGE(AE4:AH4) -> 2.75
A5: 243 | B5: Yes | C5: =IF(B5="No",1,0) -> 0 | D5: Laboratory Technician | E5: =IF(OR(D5="Manager, HR", D5="Manager, Sales", D5="Manager, R&D", D5="Manufacturing Director",D5="Research Director", D5="VP, HR", D5="CEO"),1,0) -> 0 | F5: Research & Development | G5: 1 | H5: 37224 | I5: 0.22 | J5: 37.5 | K5: No | L5: 19 | M5: Man | N5: Single | O5: Travel_Rarely | P5: 2 | Q5: Bachelor's Degree | R5: Life Sciences | S5: 4 | T5: 0 | U5: 1 | V5: 3 | W5: 1 | X5: 0 | Y5: 1 | Z5: 0 | AA5: =IF(W5<=2,"Early Tenure",IF(W5<=9,"Mid Tenure","Long Tenure")) -> Early Tenure | AC5: =IF(AND(AB5<>"",AB5>DATE(2024,1,1)),1,0) -> 0 | AE5: =VLOOKUP(A5,'Employee Engagement Survey'!A7:B1476,2,FALSE) -> 2 | AF5: =VLOOKUP(A5,'Employee Engagement Survey'!A7:C1476,3,FALSE) -> 4 | AG5: =VLOOKUP(A5,'Employee Engagement Survey'!A7:D1476,4,FALSE) -> 3 | AH5: =VLOOKUP(A5,'Employee Engagement Survey'!A7:E1476,5,FALSE) -> 2 | AI5: =AVERAGE(AE5:AH5) -> 2.75
A6: 1273 | B6: Yes | C6: =IF(B6="No",1,0) -> 0 | D6: Sales Representative | E6: =IF(OR(D6="Manager, HR", D6="Manager, Sales", D6="Manager, R&D", D6="Manufacturing Director",D6="Research Director", D6="VP, HR", D6="CEO"),1,0) -> 0 | F6: Sales | G6: 1 | H6: 37416 | I6: 0.14 | J6: 37.5 | K6: Yes | L6: 25 | M6: Man | N6: Single | O6: Travel_Frequently | P6: 24 | Q6: Trades Apprenticeship | R6: Life Sciences | S6: 3 | T6: 0 | U6: 1 | V6: 4 | W6: 1 | X6: 0 | Y6: 1 | Z6: 0 | AA6: =IF(W6<=2,"Early Tenure",IF(W6<=9,"Mid Tenure","Long Tenure")) -> Early Tenure | AC6: =IF(AND(AB6<>"",AB6>DATE(2024,1,1)),1,0) -> 0 | AE6: =VLOOKUP(A6,'Employee Engagement Survey'!A8:B1477,2,FALSE) -> 3 | AF6: =VLOOKUP(A6,'Employee Engagement Survey'!A8:C1477,3,FALSE) -> 4 | AG6: =VLOOKUP(A6,'Employee Engagement Survey'!A8:D1477,4,FALSE) -> 4 | AH6: =VLOOKUP(A6,'Employee Engagement Survey'!A8:E1477,5,FALSE) -> 3 | AI6: =AVERAGE(AE6:AH6) -> 3.5
A7: 1433 | B7: Yes | C7: =IF(B7="No",1,0) -> 0 | D7: Research Scientist | E7: =IF(OR(D7="Manager, HR", D7="Manager, Sales", D7="Manager, R&D", D7="Manufacturing Director",D7="Research Director", D7="VP, HR", D7="CEO"),1,0) -> 0 | F7: Research & Development | G7: 1 | H7: 39132 | I7: 0.12 | J7: 37.5 | K7: No | L7: 31 | M7: Woman | N7: Single | O7: Travel_Rarely | P7: 8 | Q7: Bachelor's Degree | R7: Life Sciences | S7: 3 | T7: 0 | U7: 1 | V7: 3 | W7: 1 | X7: 0 | Y7: 0 | Z7: 0 | AA7: =IF(W7<=2,"Early Tenure",IF(W7<=9,"Mid Tenure","Long Tenure")) -> Early Tenure | AC7: =IF(AND(AB7<>"",AB7>DATE(2024,1,1)),1,0) -> 0 | AE7: =VLOOKUP(A7,'Employee Engagement Survey'!A13:B1482,2,FALSE) -> 1 | AF7: =VLOOKUP(A7,'Employee Engagement Survey'!A13:C1482,3,FALSE) -> 2 | AG7: =VLOOKUP(A7,'Employee Engagement Survey'!A13:D1482,4,FALSE) -> 3 | AH7: =VLOOKUP(A7,'Employee Engagement Survey'!A13:E1482,5,FALSE) -> 4 | AI7: =AVERAGE(AE7:AH7) -> 2.5
A8: 1427 | B8: Yes | C8: =IF(B8="No",1,0) -> 0 | D8: Sales Representative | E8: =IF(OR(D8="Manager, HR", D8="Manager, Sales", D8="Manager, R&D", D8="Manufacturing Director",D8="Research Director", D8="VP, HR", D8="CEO"),1,0) -> 0 | F8: Sales | G8: 2 | H8: 40308 | I8: 0.12 | J8: 37.5 | K8: No | L8: 31 | M8: Woman | N8: Single | O8: Travel_Frequently | P8: 1 | Q8: Master's Degree | R8: Life Sciences | S8: 3 | T8: 0 | U8: 1 | V8: 3 | W8: 1 | X8: 0 | Y8: 0 | Z8: 0 | AA8: =IF(W8<=2,"Early Tenure",IF(W8<=9,"Mid Tenure","Long Tenure")) -> Early Tenure | AC8: =IF(AND(AB8<>"",AB8>DATE(2024,1,1)),1,0) -> 0 | AE8: =VLOOKUP(A8,'Employee Engagement Survey'!A16:B1485,2,FALSE) -> 2 | AF8: =VLOOKUP(A8,'Employee Engagement Survey'!A16:C1485,3,FALSE) -> 3 | AG8: =VLOOKUP(A8,'Employee Engagement Survey'!A16:D1485,4,FALSE) -> 2 | AH8: =VLOOKUP(A8,'Employee Engagement Survey'!A16:E1485,5,FALSE) -> 3 | AI8: =AVERAGE(AE8:AH8) -> 2.5
A9: 1692 | B9: Yes | C9: =IF(B9="No",1,0) -> 0 | D9: Laboratory Technician | E9: =IF(OR(D9="Manager, HR", D9="Manager, Sales", D9="Manager, R&D", D9="Manufacturing Director",D9="Research Director", D9="VP, HR", D9="CEO"),1,0) -> 0 | F9: Research & Development | G9: 2 | H9: 40716 | I9: 0.12 | J9: 37.5 | K9: No | L9: 32 | M9: Man | N9: Single | O9: Travel_Rarely | P9: 2 | Q9: Master's Degree | R9: Life Sciences | S9: 3 | T9: 0 | U9: 1 | V9: 2 | W9: 1 | X9: 0 | Y9: 0 | Z9: 0 | AA9: =IF(W9<=2,"Early Tenure",IF(W9<=9,"Mid Tenure","Long Tenure")) -> Early Tenure | AC9: =IF(AND(AB9<>"",AB9>DATE(2024,1,1)),1,0) -> 0 | AE9: =VLOOKUP(A9,'Employee Engagement Survey'!A17:B1486,2,FALSE) -> 4 | AF9: =VLOOKUP(A9,'Employee Engagement Survey'!A17:C1486,3,FALSE) -> 2 | AG9: =VLOOKUP(A9,'Employee Engagement Survey'!A17:D1486,4,FALSE) -> 1 | AH9: =VLOOKUP(A9,'Employee Engagement Survey'!A17:E1486,5,FALSE) -> 3 | AI9: =AVERAGE(AE9:AH9) -> 2.5
A10: 1079 | B10: Yes | C10: =IF(B10="No",1,0) -> 0 | D10: Laboratory Technician | E10: =IF(OR(D10="Manager, HR", D10="Manager, Sales", D10="Manager, R&D", D10="Manufacturing Director",D10="Research Director", D10="VP, HR", D10="CEO"),1,0) -> 0 | F10: Research & Development | G10: 2 | H10: 40992 | I10: 0.13 | J10: 37.5 | K10: No | L10: 21 | M10: Trangender | N10: Single | O10: Travel_Rarely | P10: 10 | Q10: Bachelor's Degree | R10: Life Sciences | S10: 3 | T10: 0 | U10: 1 | V10: 6 | W10: 1 | X10: 0 | Y10: 1 | Z10: 0 | AA10: =IF(W10<=2,"Early Tenure",IF(W10<=9,"Mid Tenure","Long Tenure")) -> Early Tenure | AC10: =IF(AND(AB10<>"",AB10>DATE(2024,1,1)),1,0) -> 0 | AE10: =VLOOKUP(A10,'Employee Engagement Survey'!A18:B1487,2,FALSE) -> 3 | AF10: =VLOOKUP(A10,'Employee Engagement Survey'!A18:C1487,3,FALSE) -> 1 | AG10: =VLOOKUP(A10,'Employee Engagement Survey'!A18:D1487,4,FALSE) -> 1 | AH10: =VLOOKUP(A10,'Employee Engagement Survey'!A18:E1487,5,FALSE) -> 2 | AI10: =AVERAGE(AE10:AH10) -> 1.75
A11: 405 | B11: Yes | C11: =IF(B11="No",1,0) -> 0 | D11: Laboratory Technician | E11: =IF(OR(D11="Manager, HR", D11="Manager, Sales", D11="Manager, R&D", D11="Manufacturing Director",D11="Research Director", D11="VP, HR", D11="CEO"),1,0) -> 0 | F11: Research & Development | G11: 2 | H11: 41040 | I11: 0.13 | J11: 37.5 | K11: No | L11: 18 | M11: Man | N11: Single | O11: Travel_Rarely | P11: 3 | Q11: Bachelor's Degree | R11: Life Sciences | S11: 3 | T11: 0 | U11: 0 | V11: 2 | W11: 0 | X11: 0 | Y11: 0 | Z11: 0 | AA11: =IF(W11<=2,"Early Tenure",IF(W11<=9,"Mid Tenure","Long Tenure")) -> Early Tenure | AC11: =IF(AND(AB11<>"",AB11>DATE(2024,1,1)),1,0) -> 0 | AE11: =VLOOKUP(A11,'Employee Engagement Survey'!A19:B1488,2,FALSE) -> 3 | AF11: =VLOOKUP(A11,'Employee Engagement Survey'!A19:C1488,3,FALSE) -> 3 | AG11: =VLOOKUP(A11,'Employee Engagement Survey'!A19:D1488,4,FALSE) -> 3 | AH11: =VLOOKUP(A11,'Employee Engagement Survey'!A19:E1488,5,FALSE) -> 3 | AI11: =AVERAGE(AE11:AH11) -> 3
A12: 4 | B12: Yes | C12: =IF(B12="No",1,0) -> 0 | D12: Laboratory Technician | E12: =IF(OR(D12="Manager, HR", D12="Manager, Sales", D12="Manager, R&D", D12="Manufacturing Director",D12="Research Director", D12="VP, HR", D12="CEO"),1,0) -> 0 | F12: Research & Development | G12: 3 | H12: 49080 | I12: 0.15 | J12: 37.5 | K12: Yes | L12: 37 | M12: Man | N12: Single | O12: Travel_Rarely | P12: 2 | Q12: Certificate or Diploma | R12: Other | S12: 3 | T12: 0 | U12: 7 | V12: 3 | W12: 0 | X12: 0 | Y12: 0 | Z12: 0 | AA12: =IF(W12<=2,"Early Tenure",IF(W12<=9,"Mid Tenure","Long Tenure")) -> Early Tenure | AC12: =IF(AND(AB12<>"",AB12>DATE(2024,1,1)),1,0) -> 0 | AE12: =VLOOKUP(A12,'Employee Engagement Survey'!A23:B1492,2,FALSE) -> 4 | AF12: =VLOOKUP(A12,'Employee Engagement Survey'!A23:C1492,3,FALSE) -> 3 | AG12: =VLOOKUP(A12,'Employee Engagement Survey'!A23:D1492,4,FALSE) -> 2 | AH12: =VLOOKUP(A12,'Employee Engagement Survey'!A23:E1492,5,FALSE) -> 3 | AI12: =AVERAGE(AE12:AH12) -> 3
A13: 1624 | B13: Yes | C13: =IF(B13="No",1,0) -> 0 | D13: Sales Representative | E13: =IF(OR(D13="Manager, HR", D13="Manager, Sales", D13="Manager, R&D", D13="Manufacturing Director",D13="Research Director", D13="VP, HR", D13="CEO"),1,0) -> 0 | F13: Sales | G13: 2 | H13: 42828 | I13: 0.12 | J13: 37.5 | K13: Yes | L13: 18 | M13: Woman | N13: Single | O13: Travel_Frequently | P13: 3 | Q13: Certificate or Diploma | R13: Medical | S13: 3 | T13: 0 | U13: 0 | V13: 2 | W13: 0 | X13: 0 | Y13: 0 | Z13: 0 | AA13: =IF(W13<=2,"Early Tenure",IF(W13<=9,"Mid Tenure","Long Tenure")) -> Early Tenure | AC13: =IF(AND(AB13<>"",AB13>DATE(2024,1,1)),1,0) -> 0 | AE13: =VLOOKUP(A13,'Employee Engagement Survey'!A24:B1493,2,FALSE) -> 2 | AF13: =VLOOKUP(A13,'Employee Engagement Survey'!A24:C1493,3,FALSE) -> 4 | AG13: =VLOOKUP(A13,'Employee Engagement Survey'!A24:D1493,4,FALSE) -> 3 | AH13: =VLOOKUP(A13,'Employee Engagement Survey'!A24:E1493,5,FALSE) -> 4 | AI13: =AVERAGE(AE13:AH13) -> 3.25
A14: 1248 | B14: Yes | C14: =IF(B14="No",1,0) -> 0 | D14: Research Scientist | E14: =IF(OR(D14="Manager, HR", D14="Manager, Sales", D14="Manager, R&D", D14="Manufacturing Director",D14="Research Director", D14="VP, HR", D14="CEO"),1,0) -> 0 | F14: Research & Development | G14: 3 | H14: 46308 | I14: 0.25 | J14: 37.5 | K14: Yes | L14: 19 | M14: Woman | N14: Single | O14: Non-Travel | P14: 10 | Q14: Bachelor's Degree | R14: Medical | S14: 4 | T14: 0 | U14: 1 | V14: 2 | W14: 1 | X14: 1 | Y14: 0 | Z14: 0 | AA14: =IF(W14<=2,"Early Tenure",IF(W14<=9,"Mid Tenure","Long Tenure")) -> Early Tenure | AC14: =IF(AND(AB14<>"",AB14>DATE(2024,1,1)),1,0) -> 0 | AE14: =VLOOKUP(A14,'Employee Engagement Survey'!A31:B1500,2,FALSE) -> 1 | AF14: =VLOOKUP(A14,'Employee Engagement Survey'!A31:C1500,3,FALSE) -> 2 | AG14: =VLOOKUP(A14,'Employee Engagement Survey'!A31:D1500,4,FALSE) -> 2 | AH14: =VLOOKUP(A14,'Employee Engagement Survey'!A31:E1500,5,FALSE) -> 4 | AI14: =AVERAGE(AE14:AH14) -> 2.25
A15: 16 | B15: No | C15: =IF(B15="No",1,0) -> 1 | D15: Research Scientist | E15: =IF(OR(D15="Manager, HR", D15="Manager, Sales", D15="Manager, R&D", D15="Manufacturing Director",D15="Research Director", D15="VP, HR", D15="CEO"),1,0) -> 0 | F15: Research & Development | G15: 5 | H15: 58932 | I15: 0.17 | J15: 37.5 | K15: No | L15: 31 | M15: Non-Binary | N15: Divorced | O15: Travel_Rarely | P15: 26 | Q15: Trades Apprenticeship | R15: Life Sciences | S15: 3 | T15: 1 | U15: 5 | V15: 1 | W15: 5 | X15: 2 | Y15: 4 | Z15: 3 | AA15: =IF(W15<=2,"Early Tenure",IF(W15<=9,"Mid Tenure","Long Tenure")) -> Mid Tenure | AB15: 44726 | AC15: =IF(AND(AB15<>"",AB15>DATE(2024,1,1)),1,0) -> 0 | AD15: Involuntary | AE15: =VLOOKUP(A15,'Employee Engagement Survey'!A33:B1502,2,FALSE) -> 1 | AF15: =VLOOKUP(A15,'Employee Engagement Survey'!A33:C1502,3,FALSE) -> 3 | AG15: =VLOOKUP(A15,'Employee Engagement Survey'!A33:D1502,4,FALSE) -> 4 | AH15: =VLOOKUP(A15,'Employee Engagement Survey'!A33:E1502,5,FALSE) -> 2 | AI15: =AVERAGE(AE15:AH15) -> 2.5
A16: 19 | B16: Yes | C16: =IF(B16="No",1,0) -> 0 | D16: Laboratory Technician | E16: =IF(OR(D16="Manager, HR", D16="Manager, Sales", D16="Manager, R&D", D16="Manufacturing Director",D16="Research Director", D16="VP, HR", D16="CEO"),1,0) -> 0 | F16: Research & Development | G16: 3 | H16: 48336 | I16: 0.14 | J16: 37.5 | K16: Yes | L16: 28 | M16: Non-Binary | N16: Single | O16: Travel_Rarely | P16: 24 | Q16: Bachelor's Degree | R16: Life Sciences | S16: 3 | T16: 0 | U16: 6 | V16: 4 | W16: 4 | X16: 2 | Y16: 0 | Z16: 3 | AA16: =IF(W16<=2,"Early Tenure",IF(W16<=9,"Mid Tenure","Long Tenure")) -> Mid Tenure | AC16: =IF(AND(AB16<>"",AB16>DATE(2024,1,1)),1,0) -> 0 | AE16: =VLOOKUP(A16,'Employee Engagement Survey'!A37:B1506,2,FALSE) -> 3 | AF16: =VLOOKUP(A16,'Employee Engagement Survey'!A37:C1506,3,FALSE) -> 3 | AG16: =VLOOKUP(A16,'Employee Engagement Survey'!A37:D1506,4,FALSE) -> 2 | AH16: =VLOOKUP(A16,'Employee Engagement Survey'!A37:E1506,5,FALSE) -> 3 | AI16: =AVERAGE(AE16:AH16) -> 2.75
A17: 881 | B17: Yes | C17: =IF(B17="No",1,0) -> 0 | D17: Research Scientist | E17: =IF(OR(D17="Manager, HR", D17="Manager, Sales", D17="Manager, R&D", D17="Manufacturing Director",D17="Research Director", D17="VP, HR", D17="CEO"),1,0) -> 0 | F17: Research & Development | G17: 3 | H17: 48264 | I17: 0.19 | J17: 37.5 | K17: Yes | L17: 35 | M17: Woman | N17: Divorced | O17: Travel_Frequently | P17: 25 | Q17: Master's Degree | R17: Life Sciences | S17: 3 | T17: 1 | U17: 10 | V17: 3 | W17: 10 | X17: 2 | Y17: 7 | Z17: 8 | AA17: =IF(W17<=2,"Early Tenure",IF(W17<=9,"Mid Tenure","Long Tenure")) -> Long Tenure | AC17: =IF(AND(AB17<>"",AB17>DATE(2024,1,1)),1,0) -> 0 | AE17: =VLOOKUP(A17,'Employee Engagement Survey'!A43:B1512,2,FALSE) -> 4 | AF17: =VLOOKUP(A17,'Employee Engagement Survey'!A43:C1512,3,FALSE) -> 2 | AG17: =VLOOKUP(A17,'Employee Engagement Survey'!A43:D1512,4,FALSE) -> 1 | AH17: =VLOOKUP(A17,'Employee Engagement Survey'!A43:E1512,5,FALSE) -> 2 | AI17: =AVERAGE(AE17:AH17) -> 2.25
A18: 27 | B18: Yes | C18: =IF(B18="No",1,0) -> 0 | D18: Sales Representative | E18: =IF(OR(D18="Manager, HR", D18="Manager, Sales", D18="Manager, R&D", D18="Manufacturing Director",D18="Research Director", D18="VP, HR", D18="CEO"),1,0) -> 0 | F18: Sales | G18: 6 | H18: 64884 | I18: 0.23 | J18: 37.5 | K18: No | L18: 36 | M18: Non-Binary | N18: Single | O18: Travel_Rarely | P18: 9 | Q18: Master's Degree | R18: Life Sciences | S18: 4 | T18: 0 | U18: 10 | V18: 4 | W18: 5 | X18: 3 | Y18: 0 | Z18: 3 | AA18: =IF(W18<=2,"Early Tenure",IF(W18<=9,"Mid Tenure","Long Tenure")) -> Mid Tenure | AC18: =IF(AND(AB18<>"",AB18>DATE(2024,1,1)),1,0) -> 0 | AE18: =VLOOKUP(A18,'Employee Engagement Survey'!A44:B1513,2,FALSE) -> 3 | AF18: =VLOOKUP(A18,'Employee Engagement Survey'!A44:C1513,3,FALSE) -> 1 | AG18: =VLOOKUP(A18,'Employee Engagement Survey'!A44:D1513,4,FALSE) -> 2 | AH18: =VLOOKUP(A18,'Employee Engagement Survey'!A44:E1513,5,FALSE) -> 3 | AI18: =AVERAGE(AE18:AH18) -> 2.25
A19: 31 | B19: Yes | C19: =IF(B19="No",1,0) -> 0 | D19: Research Scientist | E19: =IF(OR(D19="Manager, HR", D19="Manager, Sales", D19="Manager, R&D", D19="Manufacturing Director",D19="Research Director", D19="VP, HR", D19="CEO"),1,0) -> 0 | F19: Research & Development | G19: 5 | H19: 59520 | I19: 0.11 | J19: 37.5 | K19: No | L19: 34 | M19: Non-Binary | N19: Single | O19: Travel_Rarely | P19: 6 | Q19: Trades Apprenticeship | R19: Medical | S19: 3 | T19: 0 | U19: 8 | V19: 2 | W19: 4 | X19: 2 | Y19: 1 | Z19: 3 | AA19: =IF(W19<=2,"Early Tenure",IF(W19<=9,"Mid Tenure","Long Tenure")) -> Mid Tenure | AC19: =IF(AND(AB19<>"",AB19>DATE(2024,1,1)),1,0) -> 0 | AE19: =VLOOKUP(A19,'Employee Engagement Survey'!A45:B1514,2,FALSE) -> 2 | AF19: =VLOOKUP(A19,'Employee Engagement Survey'!A45:C1514,3,FALSE) -> 1 | AG19: =VLOOKUP(A19,'Employee Engagement Survey'!A45:D1514,4,FALSE) -> 3 | AH19: =VLOOKUP(A19,'Employee Engagement Survey'!A45:E1514,5,FALSE) -> 3 | AI19: =AVERAGE(AE19:AH19) -> 2.25
A20: 922 | B20: Yes | C20: =IF(B20="No",1,0) -> 0 | D20: Sales Representative | E20: =IF(OR(D20="Manager, HR", D20="Manager, Sales", D20="Manager, R&D", D20="Manufacturing Director",D20="Research Director", D20="VP, HR", D20="CEO"),1,0) -> 0 | F20: Sales | G20: 3 | H20: 48528 | I20: 0.13 | J20: 37.5 | K20: No | L20: 20 | M20: Woman | N20: Single | O20: Travel_Rarely | P20: 2 | Q20: Bachelor's Degree | R20: Medical | S20: 3 | T20: 0 | U20: 2 | V20: 3 | W20: 2 | X20: 2 | Y20: 0 | Z20: 2 | AA20: =IF(W20<=2,"Early Tenure",IF(W20<=9,"Mid Tenure","Long Tenure")) -> Early Tenure | AC20: =IF(AND(AB20<>"",AB20>DATE(2024,1,1)),1,0) -> 0 | AE20: =VLOOKUP(A20,'Employee Engagement Survey'!A52:B1521,2,FALSE) -> 3 | AF20: =VLOOKUP(A20,'Employee Engagement Survey'!A52:C1521,3,FALSE) -> 3 | AG20: =VLOOKUP(A20,'Employee Engagement Survey'!A52:D1521,4,FALSE) -> 4 | AH20: =VLOOKUP(A20,'Employee Engagement Survey'!A52:E1521,5,FALSE) -> 2 | AI20: =AVERAGE(AE20:AH20) -> 3
A21: 42 | B21: Yes | C21: =IF(B21="No",1,0) -> 0 | D21: Sales Representative | E21: =IF(OR(D21="Manager, HR", D21="Manager, Sales", D21="Manager, R&D", D21="Manufacturing Director",D21="Research Director", D21="VP, HR", D21="CEO"),1,0) -> 0 | F21: Sales | G21: 3 | H21: 49032 | I21: 0.14 | J21: 37.5 | K21: No | L21: 39 | M21: Non-Binary | N21: Married | O21: Travel_Rarely | P21: 5 | Q21: Bachelor's Degree | R21: Technical Degree | S21: 3 | T21: 1 | U21: 19 | V21: 6 | W21: 1 | X21: 0 | Y21: 0 | Z21: 0 | AA21: =IF(W21<=2,"Early Tenure",IF(W21<=9,"Mid Tenure","Long Tenure")) -> Early Tenure | AC21: =IF(AND(AB21<>"",AB21>DATE(2024,1,1)),1,0) -> 0 | AE21: =VLOOKUP(A21,'Employee Engagement Survey'!A53:B1522,2,FALSE) -> 4 | AF21: =VLOOKUP(A21,'Employee Engagement Survey'!A53:C1522,3,FALSE) -> 4 | AG21: =VLOOKUP(A21,'Employee Engagement Survey'!A53:D1522,4,FALSE) -> 3 | AH21: =VLOOKUP(A21,'Employee Engagement Survey'!A53:E1522,5,FALSE) -> 4 | AI21: =AVERAGE(AE21:AH21) -> 3.75
A22: 45 | B22: Yes | C22: =IF(B22="No",1,0) -> 0 | D22: Research Scientist | E22: =IF(OR(D22="Manager, HR", D22="Manager, Sales", D22="Manager, R&D", D22="Manufacturing Director",D22="Research Director", D22="VP, HR", D22="CEO"),1,0) -> 0 | F22: Research & Development | G22: 4 | H22: 51516 | I22: 0.16 | J22: 37.5 | K22: Yes | L22: 24 | M22: Non-Binary | N22: Married | O22: Travel_Rarely | P22: 1 | Q22: Bachelor's Degree | R22: Medical | S22: 3 | T22: 1 | U22: 6 | V22: 2 | W22: 2 | X22: 0 | Y22: 2 | Z22: 0 | AA22: =IF(W22<=2,"Early Tenure",IF(W22<=9,"Mid Tenure","Long Tenure")) -> Early Tenure | AC22: =IF(AND(AB22<>"",AB22>DATE(2024,1,1)),1,0) -> 0 | AE22: =VLOOKUP(A22,'Employee Engagement Survey'!A54:B1523,2,FALSE) -> 2 | AF22: =VLOOKUP(A22,'Employee Engagement Survey'!A54:C1523,3,FALSE) -> 4 | AG22: =VLOOKUP(A22,'Employee Engagement Survey'!A54:D1523,4,FALSE) -> 1 | AH22: =VLOOKUP(A22,'Employee Engagement Survey'!A54:E1523,5,FALSE) -> 2 | AI22: =AVERAGE(AE22:AH22) -> 2.25
A23: 47 | B23: Yes | C23: =IF(B23="No",1,0) -> 0 | D23: Sales Representative | E23: =IF(OR(D23="Manager, HR", D23="Manager, Sales", D23="Manager, R&D", D23="Manufacturing Director",D23="Research Director", D23="VP, HR", D23="CEO"),1,0) -> 0 | F23: Sales | G23: 5 | H23: 56196 | I23: 0.14 | J23: 37.5 | K23: Yes | L23: 50 | M23: Non-Binary | N23: Married | O23: Travel_Rarely | P23: 3 | Q23: Certificate or Diploma | R23: Marketing | S23: 3 | T23: 0 | U23: 3 | V23: 2 | W23: 3 | X23: 2 | Y23: 0 | Z23: 2 | AA23: =IF(W23<=2,"Early Tenure",IF(W23<=9,"Mid Tenure","Long Tenure")) -> Mid Tenure | AC23: =IF(AND(AB23<>"",AB23>DATE(2024,1,1)),1,0) -> 0 | AE23: =VLOOKUP(A23,'Employee Engagement Survey'!A55:B1524,2,FALSE) -> 1 | AF23: =VLOOKUP(A23,'Employee Engagement Survey'!A55:C1524,3,FALSE) -> 3 | AG23: =VLOOKUP(A23,'Employee Engagement Survey'!A55:D1524,4,FALSE) -> 3 | AH23: =VLOOKUP(A23,'Employee Engagement Survey'!A55:E1524,5,FALSE) -> 3 | AI23: =AVERAGE(AE23:AH23) -> 2.5
A24: 55 | B24: Yes | C24: =IF(B24="No",1,0) -> 0 | D24: Laboratory Technician | E24: =IF(OR(D24="Manager, HR", D24="Manager, Sales", D24="Manager, R&D", D24="Manufacturing Director",D24="Research Director", D24="VP, HR", D24="CEO"),1,0) -> 0 | F24: Research & Development | G24: 4 | H24: 51516 | I24: 0.12 | J24: 37.5 | K24: No | L24: 26 | M24: Non-Binary | N24: Single | O24: Travel_Rarely | P24: 25 | Q24: Bachelor's Degree | R24: Life Sciences | S24: 3 | T24: 0 | U24: 1 | V24: 2 | W24: 1 | X24: 0 | Y24: 0 | Z24: 1 | AA24: =IF(W24<=2,"Early Tenure",IF(W24<=9,"Mid Tenure","Long Tenure")) -> Early Tenure | AC24: =IF(AND(AB24<>"",AB24>DATE(2024,1,1)),1,0) -> 0 | AE24: =VLOOKUP(A24,'Employee Engagement Survey'!A58:B1527,2,FALSE) -> 1 | AF24: =VLOOKUP(A24,'Employee Engagement Survey'!A58:C1527,3,FALSE) -> 3 | AG24: =VLOOKUP(A24,'Employee Engagement Survey'!A58:D1527,4,FALSE) -> 3 | AH24: =VLOOKUP(A24,'Employee Engagement Survey'!A58:E1527,5,FALSE) -> 2 | AI24: =AVERAGE(AE24:AH24) -> 2.25
A25: 1569 | B25: Yes | C25: =IF(B25="No",1,0) -> 0 | D25: Laboratory Technician | E25: =IF(OR(D25="Manager, HR", D25="Manager, Sales", D25="Manager, R&D", D25="Manufacturing Director",D25="Research Director", D25="VP, HR", D25="CEO"),1,0) -> 0 | F25: Research & Development | G25: 3 | H25: 48888 | I25: 0.12 | J25: 37.5 | K25: Yes | L25: 35 | M25: Woman | N25: Divorced | O25: Travel_Rarely | P25: 2 | Q25: Bachelor's Degree | R25: Life Sciences | S25: 3 | T25: 1 | U25: 1 | V25: 2 | W25: 1 | X25: 0 | Y25: 0 | Z25: 0 | AA25: =IF(W25<=2,"Early Tenure",IF(W25<=9,"Mid Tenure","Long Tenure")) -> Early Tenure | AC25: =IF(AND(AB25<>"",AB25>DATE(2024,1,1)),1,0) -> 0 | AE25: =VLOOKUP(A25,'Employee Engagement Survey'!A64:B1533,2,FALSE) -> 1 | AF25: =VLOOKUP(A25,'Employee Engagement Survey'!A64:C1533,3,FALSE) -> 1 | AG25: =VLOOKUP(A25,'Employee Engagement Survey'!A64:D1533,4,FALSE) -> 4 | AH25: =VLOOKUP(A25,'Employee Engagement Survey'!A64:E1533,5,FALSE) -> 3 | AI25: =AVERAGE(AE25:AH25) -> 2.25
A26: 64 | B26: Yes | C26: =IF(B26="No",1,0) -> 0 | D26: Laboratory Technician | E26: =IF(OR(D26="Manager, HR", D26="Manager, Sales", D26="Manager, R&D", D26="Manufacturing Director",D26="Research Director", D26="VP, HR", D26="CEO"),1,0) -> 0 | F26: Research & Development | G26: 7 | H26: 76572 | I26: 0.13 | J26: 37.5 | K26: Yes | L26: 48 | M26: Man | N26: Single | O26: Travel_Rarely | P26: 1 | Q26: Certificate or Diploma | R26: Life Sciences | S26: 3 | T26: 0 | U26: 23 | V26: 2 | W26: 1 | X26: 0 | Y26: 0 | Z26: 0 | AA26: =IF(W26<=2,"Early Tenure",IF(W26<=9,"Mid Tenure","Long Tenure")) -> Early Tenure | AC26: =IF(AND(AB26<>"",AB26>DATE(2024,1,1)),1,0) -> 0 | AE26: =VLOOKUP(A26,'Employee Engagement Survey'!A68:B1537,2,FALSE) -> 1 | AF26: =VLOOKUP(A26,'Employee Engagement Survey'!A68:C1537,3,FALSE) -> 3 | AG26: =VLOOKUP(A26,'Employee Engagement Survey'!A68:D1537,4,FALSE) -> 4 | AH26: =VLOOKUP(A26,'Employee Engagement Survey'!A68:E1537,5,FALSE) -> 3 | AI26: =AVERAGE(AE26:AH26) -> 2.75
A27: 65 | B27: Yes | C27: =IF(B27="No",1,0) -> 0 | D27: Laboratory Technician | E27: =IF(OR(D27="Manager, HR", D27="Manager, Sales", D27="Manager, R&D", D27="Manufacturing Director",D27="Research Director", D27="VP, HR", D27="CEO"),1,0) -> 0 | F27: Research & Development | G27: 6 | H27: 65292 | I27: 0.13 | J27: 37.5 | K27: Yes | L27: 28 | M27: Man | N27: Single | O27: Travel_Rarely | P27: 5 | Q27: Master's Degree | R27: Technical Degree | S27: 3 | T27: 0 | U27: 2 | V27: 3 | W27: 2 | X27: 2 | Y27: 2 | Z27: 2 | AA27: =IF(W27<=2,"Early Tenure",IF(W27<=9,"Mid Tenure","Long Tenure")) -> Early Tenure | AC27: =IF(AND(AB27<>"",AB27>DATE(2024,1,1)),1,0) -> 0 | AE27: =VLOOKUP(A27,'Employee Engagement Survey'!A69:B1538,2,FALSE) -> 3 | AF27: =VLOOKUP(A27,'Employee Engagement Survey'!A69:C1538,3,FALSE) -> 3 | AG27: =VLOOKUP(A27,'Employee Engagement Survey'!A69:D1538,4,FALSE) -> 3 | AH27: =VLOOKUP(A27,'Employee Engagement Survey'!A69:E1538,5,FALSE) -> 2 | AI27: =AVERAGE(AE27:AH27) -> 2.75
A28: 90 | B28: Yes | C28: =IF(B28="No",1,0) -> 0 | D28: Research Scientist | E28: =IF(OR(D28="Manager, HR", D28="Manager, Sales", D28="Manager, R&D", D28="Manufacturing Director",D28="Research Director", D28="VP, HR", D28="CEO"),1,0) -> 0 | F28: Research & Development | G28: 6 | H28: 64656 | I28: 0.17 | J28: 37.5 | K28: Yes | L28: 36 | M28: Man | N28: Married | O28: Travel_Rarely | P28: 9 | Q28: Bachelor's Degree | R28: Medical | S28: 3 | T28: 1 | U28: 2 | V28: 0 | W28: 1 | X28: 0 | Y28: 0 | Z28: 0 | AA28: =IF(W28<=2,"Early Tenure",IF(W28<=9,"Mid Tenure","Long Tenure")) -> Early Tenure | AC28: =IF(AND(AB28<>"",AB28>DATE(2024,1,1)),1,0) -> 0 | AE28: =VLOOKUP(A28,'Employee Engagement Survey'!A83:B1552,2,FALSE) -> 4 | AF28: =VLOOKUP(A28,'Employee Engagement Survey'!A83:C1552,3,FALSE) -> 3 | AG28: =VLOOKUP(A28,'Employee Engagement Survey'!A83:D1552,4,FALSE) -> 1 | AH28: =VLOOKUP(A28,'Employee Engagement Survey'!A83:E1552,5,FALSE) -> 2 | AI28: =AVERAGE(AE28:AH28) -> 2.5
A29: 1004 | B29: Yes | C29: =IF(B29="No",1,0) -> 0 | D29: Research Scientist | E29: =IF(OR(D29="Manager, HR", D29="Manager, Sales", D29="Manager, R&D", D29="Manufacturing Director",D29="Research Director", D29="VP, HR", D29="CEO"),1,0) -> 0 | F29: Research & Development | G29: 3 | H29: 49584 | I29: 0.11 | J29: 37.5 | K29: Yes | L29: 30 | M29: Woman | N29: Married | O29: Travel_Rarely | P29: 22 | Q29: Bachelor's Degree | R29: Life Sciences | S29: 3 | T29: 0 | U29: 7 | V29: 2 | W29: 5 | X29: 2 | Y29: 0 | Z29: 1 | AA29: =IF(W29<=2,"Early Tenure",IF(W29<=9,"Mid Tenure","Long Tenure")) -> Mid Tenure | AC29: =IF(AND(AB29<>"",AB29>DATE(2024,1,1)),1,0) -> 0 | AE29: =VLOOKUP(A29,'Employee Engagement Survey'!A86:B1555,2,FALSE) -> 1 | AF29: =VLOOKUP(A29,'Employee Engagement Survey'!A86:C1555,3,FALSE) -> 3 | AG29: =VLOOKUP(A29,'Employee Engagement Survey'!A86:D1555,4,FALSE) -> 2 | AH29: =VLOOKUP(A29,'Employee Engagement Survey'!A86:E1555,5,FALSE) -> 3 | AI29: =AVERAGE(AE29:AH29) -> 2.25
A30: 1818 | B30: Yes | C30: =IF(B30="No",1,0) -> 0 | D30: Compensation Analyst | E30: =IF(OR(D30="Manager, HR", D30="Manager, Sales", D30="Manager, R&D", D30="Manufacturing Director",D30="Research Director", D30="VP, HR", D30="CEO"),1,0) -> 0 | F30: Human Resources | G30: 3 | H30: 49776 | I30: 0.11 | J30: 37.5 | K30: Yes | L30: 26 | M30: Woman | N30: Married | O30: Travel_Rarely | P30: 20 | Q30: Certificate or Diploma | R30: Medical | S30: 3 | T30: 0 | U30: 6 | V30: 3 | W30: 5 | X30: 1 | Y30: 1 | Z30: 4 | AA30: =IF(W30<=2,"Early Tenure",IF(W30<=9,"Mid Tenure","Long Tenure")) -> Mid Tenure | AC30: =IF(AND(AB30<>"",AB30>DATE(2024,1,1)),1,0) -> 0 | AE30: =VLOOKUP(A30,'Employee Engagement Survey'!A93:B1562,2,FALSE) -> 4 | AF30: =VLOOKUP(A30,'Employee Engagement Survey'!A93:C1562,3,FALSE) -> 2 | AG30: =VLOOKUP(A30,'Employee Engagement Survey'!A93:D1562,4,FALSE) -> 3 | AH30: =VLOOKUP(A30,'Employee Engagement Survey'!A93:E1562,5,FALSE) -> 3 | AI30: =AVERAGE(AE30:AH30) -> 3
A31: 478 | B31: Yes | C31: =IF(B31="No",1,0) -> 0 | D31: Sales Representative | E31: =IF(OR(D31="Manager, HR", D31="Manager, Sales", D31="Manager, R&D", D31="Manufacturing Director",D31="Research Director", D31="VP, HR", D31="CEO"),1,0) -> 0 | F31: Sales | G31: 4 | H31: 50088 | I31: 0.11 | J31: 37.5 | K31: Yes | L31: 21 | M31: Woman | N31: Single | O31: Travel_Frequently | P31: 1 | Q31: Trades Apprenticeship | R31: Technical Degree | S31: 3 | T31: 0 | U31: 3 | V31: 3 | W31: 3 | X31: 2 | Y31: 1 | Z31: 2 | AA31: =IF(W31<=2,"Early Tenure",IF(W31<=9,"Mid Tenure","Long Tenure")) -> Mid Tenure | AC31: =IF(AND(AB31<>"",AB31>DATE(2024,1,1)),1,0) -> 0 | AE31: =VLOOKUP(A31,'Employee Engagement Survey'!A99:B1568,2,FALSE) -> 1 | AF31: =VLOOKUP(A31,'Employee Engagement Survey'!A99:C1568,3,FALSE) -> 2 | AG31: =VLOOKUP(A31,'Employee Engagement Survey'!A99:D1568,4,FALSE) -> 3 | AH31: =VLOOKUP(A31,'Employee Engagement Survey'!A99:E1568,5,FALSE) -> 3 | AI31: =AVERAGE(AE31:AH31) -> 2.25
A32: 1747 | B32: Yes | C32: =IF(B32="No",1,0) -> 0 | D32: HR Operations Specialist | E32: =IF(OR(D32="Manager, HR", D32="Manager, Sales", D32="Manager, R&D", D32="Manufacturing Director",D32="Research Director", D32="VP, HR", D32="CEO"),1,0) -> 0 | F32: Human Resources | G32: 4 | H32: 50160 | I32: 0.11 | J32: 37.5 | K32: No | L32: 30 | M32: Woman | N32: Divorced | O32: Travel_Frequently | P32: 8 | Q32: Bachelor's Degree | R32: Human Resources | S32: 3 | T32: 1 | U32: 6 | V32: 0 | W32: 4 | X32: 2 | Y32: 1 | Z32: 2 | AA32: =IF(W32<=2,"Early Tenure",IF(W32<=9,"Mid Tenure","Long Tenure")) -> Mid Tenure | AC32: =IF(AND(AB32<>"",AB32>DATE(2024,1,1)),1,0) -> 0 | AE32: =VLOOKUP(A32,'Employee Engagement Survey'!A103:B1572,2,FALSE) -> 3 | AF32: =VLOOKUP(A32,'Employee Engagement Survey'!A103:C1572,3,FALSE) -> 4 | AG32: =VLOOKUP(A32,'Employee Engagement Survey'!A103:D1572,4,FALSE) -> 3 | AH32: =VLOOKUP(A32,'Employee Engagement Survey'!A103:E1572,5,FALSE) -> 2 | AI32: =AVERAGE(AE32:AH32) -> 3
A33: 118 | B33: Yes | C33: =IF(B33="No",1,0) -> 0 | D33: Sales Executive | E33: =IF(OR(D33="Manager, HR", D33="Manager, Sales", D33="Manager, R&D", D33="Manufacturing Director",D33="Research Director", D33="VP, HR", D33="CEO"),1,0) -> 0 | F33: Sales | G33: 9 | H33: 127428 | I33: 0.16 | J33: 37.5 | K33: No | L33: 46 | M33: Man | N33: Single | O33: Travel_Rarely | P33: 9 | Q33: Certificate or Diploma | R33: Medical | S33: 3 | T33: 0 | U33: 9 | V33: 3 | W33: 9 | X33: 8 | Y33: 4 | Z33: 7 | AA33: =IF(W33<=2,"Early Tenure",IF(W33<=9,"Mid Tenure","Long Tenure")) -> Mid Tenure | AC33: =IF(AND(AB33<>"",AB33>DATE(2024,1,1)),1,0) -> 0 | AE33: =VLOOKUP(A33,'Employee Engagement Survey'!A109:B1578,2,FALSE) -> 3 | AF33: =VLOOKUP(A33,'Employee Engagement Survey'!A109:C1578,3,FALSE) -> 4 | AG33: =VLOOKUP(A33,'Employee Engagement Survey'!A109:D1578,4,FALSE) -> 4 | AH33: =VLOOKUP(A33,'Employee Engagement Survey'!A109:E1578,5,FALSE) -> 3 | AI33: =AVERAGE(AE33:AH33) -> 3.5
A34: 1219 | B34: Yes | C34: =IF(B34="No",1,0) -> 0 | D34: Laboratory Technician | E34: =IF(OR(D34="Manager, HR", D34="Manager, Sales", D34="Manager, R&D", D34="Manufacturing Director",D34="Research Director", D34="VP, HR", D34="CEO"),1,0) -> 0 | F34: Research & Development | G34: 4 | H34: 50520 | I34: 0.13 | J34: 37.5 | K34: No | L34: 24 | M34: Woman | N34: Married | O34: Travel_Rarely | P34: 17 | Q34: Certificate or Diploma | R34: Life Sciences | S34: 3 | T34: 1 | U34: 1 | V34: 3 | W34: 1 | X34: 0 | Y34: 0 | Z34: 0 | AA34: =IF(W34<=2,"Early Tenure",IF(W34<=9,"Mid Tenure","Long Tenure")) -> Early Tenure | AC34: =IF(AND(AB34<>"",AB34>DATE(2024,1,1)),1,0) -> 0 | AE34: =VLOOKUP(A34,'Employee Engagement Survey'!A110:B1579,2,FALSE) -> 4 | AF34: =VLOOKUP(A34,'Employee Engagement Survey'!A110:C1579,3,FALSE) -> 2 | AG34: =VLOOKUP(A34,'Employee Engagement Survey'!A110:D1579,4,FALSE) -> 1 | AH34: =VLOOKUP(A34,'Employee Engagement Survey'!A110:E1579,5,FALSE) -> 1 | AI34: =AVERAGE(AE34:AH34) -> 2
A35: 741 | B35: Yes | C35: =IF(B35="No",1,0) -> 0 | D35: Research Scientist | E35: =IF(OR(D35="Manager, HR", D35="Manager, Sales", D35="Manager, R&D", D35="Manufacturing Director",D35="Research Director", D35="VP, HR", D35="CEO"),1,0) -> 0 | F35: Research & Development | G35: 4 | H35: 50592 | I35: 0.13 | J35: 37.5 | K35: Yes | L35: 28 | M35: Woman | N35: Single | O35: Travel_Rarely | P35: 1 | Q35: Certificate or Diploma | R35: Life Sciences | S35: 3 | T35: 0 | U35: 10 | V35: 4 | W35: 7 | X35: 7 | Y35: 3 | Z35: 7 | AA35: =IF(W35<=2,"Early Tenure",IF(W35<=9,"Mid Tenure","Long Tenure")) -> Mid Tenure | AC35: =IF(AND(AB35<>"",AB35>DATE(2024,1,1)),1,0) -> 0 | AE35: =VLOOKUP(A35,'Employee Engagement Survey'!A112:B1581,2,FALSE) -> 1 | AF35: =VLOOKUP(A35,'Employee Engagement Survey'!A112:C1581,3,FALSE) -> 2 | AG35: =VLOOKUP(A35,'Employee Engagement Survey'!A112:D1581,4,FALSE) -> 4 | AH35: =VLOOKUP(A35,'Employee Engagement Survey'!A112:E1581,5,FALSE) -> 3 | AI35: =AVERAGE(AE35:AH35) -> 2.5
A36: 133 | B36: Yes | C36: =IF(B36="No",1,0) -> 0 | D36: HR Business Partner | E36: =IF(OR(D36="Manager, HR", D36="Manager, Sales", D36="Manager, R&D", D36="Manufacturing Director",D36="Research Director", D36="VP, HR", D36="CEO"),1,0) -> 0 | F36: Human Resources | G36: 3 | H36: 48876 | I36: 0.22 | J36: 37.5 | K36: Yes | L36: 37 | M36: Man | N36: Divorced | O36: Travel_Rarely | P36: 6 | Q36: Master's Degree | R36: Human Resources | S36: 4 | T36: 0 | U36: 7 | V36: 3 | W36: 3 | X36: 2 | Y36: 0 | Z36: 2 | AA36: =IF(W36<=2,"Early Tenure",IF(W36<=9,"Mid Tenure","Long Tenure")) -> Mid Tenure | AC36: =IF(AND(AB36<>"",AB36>DATE(2024,1,1)),1,0) -> 0 | AE36: =VLOOKUP(A36,'Employee Engagement Survey'!A124:B1593,2,FALSE) -> 3 | AF36: =VLOOKUP(A36,'Employee Engagement Survey'!A124:C1593,3,FALSE) -> 1 | AG36: =VLOOKUP(A36,'Employee Engagement Survey'!A124:D1593,4,FALSE) -> 4 | AH36: =VLOOKUP(A36,'Employee Engagement Survey'!A124:E1593,5,FALSE) -> 3 | AI36: =AVERAGE(AE36:AH36) -> 2.75
A37: 142 | B37: Yes | C37: =IF(B37="No",1,0) -> 0 | D37: Sales Executive | E37: =IF(OR(D37="Manager, HR", D37="Manager, Sales", D37="Manager, R&D", D37="Manufacturing Director",D37="Research Director", D37="VP, HR", D37="CEO"),1,0) -> 0 | F37: Sales | G37: 7 | H37: 80928 | I37: 0.11 | J37: 37.5 | K37: Yes | L37: 25 | M37: Man | N37: Single | O37: Travel_Rarely | P37: 5 | Q37: Bachelor's Degree | R37: Marketing | S37: 3 | T37: 0 | U37: 6 | V37: 1 | W37: 6 | X37: 4 | Y37: 0 | Z37: 3 | AA37: =IF(W37<=2,"Early Tenure",IF(W37<=9,"Mid Tenure","Long Tenure")) -> Mid Tenure | AC37: =IF(AND(AB37<>"",AB37>DATE(2024,1,1)),1,0) -> 0 | AE37: =VLOOKUP(A37,'Employee Engagement Survey'!A128:B1597,2,FALSE) -> 3 | AF37: =VLOOKUP(A37,'Employee Engagement Survey'!A128:C1597,3,FALSE) -> 3 | AG37: =VLOOKUP(A37,'Employee Engagement Survey'!A128:D1597,4,FALSE) -> 4 | AH37: =VLOOKUP(A37,'Employee Engagement Survey'!A128:E1597,5,FALSE) -> 3 | AI37: =AVERAGE(AE37:AH37) -> 3.25
A38: 147 | B38: Yes | C38: =IF(B38="No",1,0) -> 0 | D38: Laboratory Technician | E38: =IF(OR(D38="Manager, HR", D38="Manager, Sales", D38="Manager, R&D", D38="Manufacturing Director",D38="Research Director", D38="VP, HR", D38="CEO"),1,0) -> 0 | F38: Research & Development | G38: 7 | H38: 84888 | I38: 0.24 | J38: 37.5 | K38: Yes | L38: 34 | M38: Man | N38: Single | O38: Travel_Frequently | P38: 7 | Q38: Bachelor's Degree | R38: Life Sciences | S38: 4 | T38: 0 | U38: 9 | V38: 3 | W38: 9 | X38: 7 | Y38: 0 | Z38: 6 | AA38: =IF(W38<=2,"Early Tenure",IF(W38<=9,"Mid Tenure","Long Tenure")) -> Mid Tenure | AC38: =IF(AND(AB38<>"",AB38>DATE(2024,1,1)),1,0) -> 0 | AE38: =VLOOKUP(A38,'Employee Engagement Survey'!A131:B1600,2,FALSE) -> 1 | AF38: =VLOOKUP(A38,'Employee Engagement Survey'!A131:C1600,3,FALSE) -> 3 | AG38: =VLOOKUP(A38,'Employee Engagement Survey'!A131:D1600,4,FALSE) -> 4 | AH38: =VLOOKUP(A38,'Employee Engagement Survey'!A131:E1600,5,FALSE) -> 3 | AI38: =AVERAGE(AE38:AH38) -> 2.75
A39: 163 | B39: Yes | C39: =IF(B39="No",1,0) -> 0 | D39: Sales Executive | E39: =IF(OR(D39="Manager, HR", D39="Manager, Sales", D39="Manager, R&D", D39="Manufacturing Director",D39="Research Director", D39="VP, HR", D39="CEO"),1,0) -> 0 | F39: Sales | G39: 8 | H39: 86064 | I39: 0.18 | J39: 37.5 | K39: Yes | L39: 31 | M39: Man | N39: Married | O39: Travel_Rarely | P39: 6 | Q39: Master's Degree | R39: Life Sciences | S39: 3 | T39: 0 | U39: 12 | V39: 3 | W39: 7 | X39: 7 | Y39: 7 | Z39: 7 | AA39: =IF(W39<=2,"Early Tenure",IF(W39<=9,"Mid Tenure","Long Tenure")) -> Mid Tenure | AC39: =IF(AND(AB39<>"",AB39>DATE(2024,1,1)),1,0) -> 0 | AE39: =VLOOKUP(A39,'Employee Engagement Survey'!A140:B1609,2,FALSE) -> 2 | AF39: =VLOOKUP(A39,'Employee Engagement Survey'!A140:C1609,3,FALSE) -> 3 | AG39: =VLOOKUP(A39,'Employee Engagement Survey'!A140:D1609,4,FALSE) -> 2 | AH39: =VLOOKUP(A39,'Employee Engagement Survey'!A140:E1609,5,FALSE) -> 2 | AI39: =AVERAGE(AE39:AH39) -> 2.25
A40: 1331 | B40: Yes | C40: =IF(B40="No",1,0) -> 0 | D40: Sales Representative | E40: =IF(OR(D40="Manager, HR", D40="Manager, Sales", D40="Manager, R&D", D40="Manufacturing Director",D40="Research Director", D40="VP, HR", D40="CEO"),1,0) -> 0 | F40: Sales | G40: 4 | H40: 51624 | I40: 0.11 | J40: 37.5 | K40: Yes | L40: 31 | M40: Non-Binary | N40: Single | O40: Travel_Frequently | P40: 1 | Q40: Bachelor's Degree | R40: Life Sciences | S40: 3 | T40: 0 | U40: 3 | V40: 2 | W40: 3 | X40: 2 | Y40: 2 | Z40: 2 | AA40: =IF(W40<=2,"Early Tenure",IF(W40<=9,"Mid Tenure","Long Tenure")) -> Mid Tenure | AC40: =IF(AND(AB40<>"",AB40>DATE(2024,1,1)),1,0) -> 0 | AE40: =VLOOKUP(A40,'Employee Engagement Survey'!A141:B1610,2,FALSE) -> 4 | AF40: =VLOOKUP(A40,'Employee Engagement Survey'!A141:C1610,3,FALSE) -> 2 | AG40: =VLOOKUP(A40,'Employee Engagement Survey'!A141:D1610,4,FALSE) -> 1 | AH40: =VLOOKUP(A40,'Employee Engagement Survey'!A141:E1610,5,FALSE) -> 4 | AI40: =AVERAGE(AE40:AH40) -> 2.75
...

Sheet H1_TenureStage
A1: H1
A2: Hypothesis: Employees with mid level tenure show higher attrition than other tenure stages.
A5: Attrition Rate per Tenure Grouping
A6: Senior Leadership Filter | B6: 1 | C6: (1=Senior Leadership role)
A8: Row Labels | B8: Sum of Recent Exit Flag | C8: Count of EmployeeNumber | D8: Attrition Rate (%) | F8: Definitions:
A9: Early Tenure | B9: 23 | C9: 42 | D9: =GETPIVOTDATA("Sum of Recent Exit Flag",$A$8,"Tenure Stage","Early Tenure")/GETPIVOTDATA("Count of EmployeeNumber",$A$8,"Tenure Stage","Early Tenure") -> 0.54761905 | F9: Early Tenure 0-2 yrs
A10: Long Tenure | B10: 61 | C10: 141 | D10: =GETPIVOTDATA("Sum of Recent Exit Flag",$A$8,"Tenure Stage","Long Tenure")/GETPIVOTDATA("Count of EmployeeNumber",$A$8,"Tenure Stage","Long Tenure") -> 0.43262411 | F10: Long 10+ yrs
A11: Mid Tenure | B11: 74 | C11: 145 | D11: =GETPIVOTDATA("Sum of Recent Exit Flag",$A$8,"Tenure Stage","Mid Tenure")/GETPIVOTDATA("Count of EmployeeNumber",$A$8,"Tenure Stage","Mid Tenure") -> 0.51034483 | F11: Mid 3-9 yrs
A12: Grand Total | B12: 158 | C12: 328 | D12: =GETPIVOTDATA("Sum of Recent Exit Flag",$A$8)/GETPIVOTDATA("Count of EmployeeNumber",$A$8) -> 0.48170732
A15: Findings
A16: Early Tenure stage has the highest attrition rate among recent exits (in 2024, 2025) of leadership population

Sheet H2_LongTenure
A1: H2
A2: Hypothesis: Employees with senior (long) tenure show higher attrition than other tenure stages.
A4: Long Tenure Attrition vs all other tenure groups
A6: Actual | G6: Expected
A7: Tenure Group | B7: Recent Exit (1) | C7: Non Recent Exit & Active (0) | D7: Row Total | E7: Attrition Rate | G7: Tenure Group | H7: Recent Exit (1) | I7: Non Recent Exit & Active (0)
A8: Long Tenure | B8: =COUNTIFS(Clean_Data!AA2:AA1472, "Long Tenure",Clean_Data!E2:E1472, 1, Clean_Data!AC2:AC1472, 1) -> 61 | C8: =COUNTIFS(Clean_Data!AA2:AA1472, "Long Tenure",Clean_Data!E2:E1472, 1, Clean_Data!AC2:AC1472, 0) -> 80 | D8: =B8+C8 -> 141 | E8: =B8/(B8+C8) -> 0.43262411 | G8: Long Tenure | H8: =D8*$B$10/$D$10 -> 67.920732 | I8: =(D8*$C$10)/$D$10 -> 73.079268
A9: Other Tenure | B9: =COUNTIFS(Clean_Data!AA2:AA1472, "<>Long Tenure", Clean_Data!E2:E1472, 1, Clean_Data!AC2:AC1472, 1) -> 97 | C9: =COUNTIFS(Clean_Data!AA2:AA1472, "<>Long Tenure", Clean_Data!E2:E1472, 1, Clean_Data!AC2:AC1472, 0) -> 90 | D9: =B9+C9 -> 187 | E9: =B9/(B9+C9) -> 0.51871658 | G9: Other Tenure | H9: =D9*$B$10/$D$10 -> 90.079268 | I9: =(D9*$C$10)/$D$10 -> 96.920732
A10: Column Total | B10: =B8+B9 -> 158 | C10: =C8+C9 -> 170 | D10: =D8+D9 -> 328
B13: Chi square test
B14: p= | C14: =_xlfn.CHISQ.TEST(B8:C9,H8:I9) -> 0.12238849
B15: p<0.05 | C15: statistically significant relationship
B16: p≥0.05 | C16: no statistial significant relationship
A19: Findings
A20: Employees with Long tenure (defined at 10+ years) have lower attrition than leaders in the other tenure stages.
A21: However, the difference is not statistically significant and supports the idea that long tenure leaders my be more retained.

Sheet H3_Department
A1: H3
A2: Hypothesis: The rate of loss among employees differ by department, with certain departments having higher risk than others
A4: Exits by Department
A5: Senior Leadership Filter | B5: 1 | C5: (1=Senior Leadership role)
A7: Count of EmployeeNumber | B7: Exit
A8: Department | B8: Not Recent (0) | C8: Recent (1) | D8: Grand Total
A9: Human Resources | B9: 7 | C9: 4 | D9: 11
A10: Research & Development | B10: 147 | C10: 133 | D10: 280
A11: Sales | B11: 16 | C11: 21 | D11: 37
A12: Grand Total | B12: 170 | C12: 158 | D12: 328
A15: Actual | F15: Expected
A16: Department | B16: Exit=0 (non recent exit & active) | C16: Exit=1 (recent exit) | D16: Row Total | F16: Department | G16: Exit=0 | H16: Exit=1
A17: Human Resources | B17: 7 | C17: 4 | D17: =B17+C17 -> 11 | F17: Human Resources | G17: =(D17*$B$20)/$D$20 -> 5.7012195 | H17: =(D17*$C$20)/$D$20 -> 5.2987805
A18: Research & Development | B18: 147 | C18: 133 | D18: =B18+C18 -> 280 | F18: Research & Development | G18: =(D18*$B$20)/$D$20 -> 145.12195 | H18: =(D18*$C$20)/$D$20 -> 134.87805
A19: Sales | B19: 16 | C19: 21 | D19: =B19+C19 -> 37 | F19: Sales | G19: =(D19*$B$20)/$D$20 -> 19.176829 | H19: =(D19*$C$20)/$D$20 -> 17.823171
A20: Column Total | B20: =B17+B18+B19 -> 170 | C20: =C17+C18+C19 -> 158 | D20: =D17+D18+D19 -> 328
C22: Chi square test
C23: p= | D23: =_xlfn.CHISQ.TEST(B17:C19,G17:H19) -> 0.41536711
C24: p<0.05 | D24: statistically significant relationship
C25: p≥0.05 | D25: no statistial significant relationship
A26: Findings
A27: No statistical significant relationship. The likelihood of a recent exit does not significantly differ by department among leadership employees

Sheet H4_TimeinRole
A1: H4
A2: Hypothesis: Leaders with longer years in current role are more likely to exit.
A4: Years in Current Role Average
A5: Recent Exit Leaders | B5: =AVERAGEIFS(Clean_Data!X2:X1472, Clean_Data!E2:E1472, 1, Clean_Data!AC2:AC1472, 1) -> 5.4936709
A6: Ron- recent exit leaders | B6: =AVERAGEIFS(Clean_Data!X2:X1472, Clean_Data!E2:E1472, 1, Clean_Data!AC2:AC1472, 0) -> 5.9823529
A8: Findings
A9: Leadership employees who exited recently had slightly fewer years in their current role compared to leaders who are active or did not exit recently.
A11: T-test
A12: p= | B12: =_xlfn.T.TEST(A19:A89,B19:B188,2,3) -> 0.64891043
A14: Findings
A15: The difference in years in role between leaders who exited recently and those who did not is not statistically significant.
A17: Years in current role
A18: Recent Exit Leaders | B18: Non Recent Exit & Active Leaders
A19: 2 | B19: 2
A20: 6 | B20: 0
A21: 6 | B21: 0
A22: 7 | B22: 7
A23: 5 | B23: 6
A24: 4 | B24: 2
A25: 0 | B25: 2
A26: 6 | B26: 15
A27: 0 | B27: 3
A28: 0 | B28: 2
A29: 0 | B29: 8
A30: 7 | B30: 2
... A89: 16 | B89: 16
B90: 2
B91: 0
B92: 4
B93: 2
B94: 2
B95: 2
B96: 2
B97: 6
B98: 4
B99: 4
B100: 0
B101: 7
... B188: 2

Sheet H5__SalesR&D
A1: H5
A2: Hypothesis: Roles in Sales and R&D experience higher attrition than leaders in other areas.
A5: Department Attrition Rate
A6: Senior Leadership Filter | B6: 1 | C6: (1=Senior Leadership role)
A8: Row Labels | B8: Sum of Recent Exit Flag | C8: Count of EmployeeNumber | E8: Attrition Rate
A9: Human Resources | B9: 4 | C9: 11 | E9: =GETPIVOTDATA("Sum of Recent Exit Flag",$A$8,"Department","Human Resources")/GETPIVOTDATA("Count of EmployeeNumber",$A$8,"Department","Human Resources") -> 0.36363636
A10: Research & Development | B10: 133 | C10: 280 | E10: =GETPIVOTDATA("Sum of Recent Exit Flag",$A$8,"Department","Research & Development")/GETPIVOTDATA("Count of EmployeeNumber",$A$8,"Department","Research & Development") -> 0.475
A11: Sales | B11: 21 | C11: 37 | E11: =GETPIVOTDATA("Sum of Recent Exit Flag",$A$8,"Department","Sales")/GETPIVOTDATA("Count of EmployeeNumber",$A$8,"Department","Sales") -> 0.56756757
A12: Grand Total | B12: 158 | C12: 328
A15: Findings
A16: Leadership roles in Sales and Research & Development experience higher attrition than leaders in other areas (HR).

Sheet H6_Travel
A1: H6
A2: Hypothesis: Employees with requirements to travel frequently are more likely to exit.
A4: Travel Frequency
A5: Senior Leadership Filter | B5: 1 | C5: (1=Senior Leadership role)
A7: Count of EmployeeNumber | B7: Exits
A8: Travel Needs | B8: 0 (Non recent & active) | C8: 1 (Recent) | D8: Grand Total
A9: Non-Travel | B9: 12 | C9: 19 | D9: 31
A10: Travel_Frequently | B10: 28 | C10: 26 | D10: 54
A11: Travel_Rarely | B11: 130 | C11: 113 | D11: 243
A12: Grand Total | B12: 170 | C12: 158 | D12: 328
A15: Actual | G15: Expected
A16: Travel Needs | B16: 0 (Non recent) | C16: 1 (Recent) | D16: Row Total | G16: Travel Needs | H16: 0 (Non recent) | I16: 1 (Recent)
A17: Non-Travel | B17: 12 | C17: 19 | D17: =B17+C17 -> 31 | G17: Non-Travel | H17: =(D17*$B$20)/$D$20 -> 16.067073 | I17: =(D17*$C$20)/$D$20 -> 14.932927
A18: Travel_Frequently | B18: 28 | C18: 26 | D18: =B18+C18 -> 54 | G18: Travel_Frequently | H18: =(D18*$B$20)/$D$20 -> 27.987805 | I18: =(D18*$C$20)/$D$20 -> 26.012195
A19: Travel_Rarely | B19: 130 | C19: 113 | D19: =B19+C19 -> 243 | G19: Travel_Rarely | H19: =(D19*$B$20)/$D$20 -> 125.94512 | I19: =(D19*$C$20)/$D$20 -> 117.05488
A20: Column Total | B20: =B17+B18+B19 -> 170 | C20: =C17+C18+C19 -> 158 | D20: =D17+D18+D19 -> 328
C23: Chi square test
C24: p= | D24: =_xlfn.CHISQ.TEST(B17:C19,H17:I19) -> 0.29995905
C25: p<0.05 | D25: statistically significant relationship
C26: p≥0.05 | D26: no statistial significant relationship
A27: Findings
A28: The likelihood of recent exits among leadership employees did not significantly differ based on travel frequency requirements.

Sheet H7_WorkLifeBalance
A1: H7
A2: Hypothesis: Employees with lower work life balance scores are more likely to leave.
A4: Work Life Balance Average
A5: Senior Leadership Filter | B5: 1 | C5: (1=Senior Leadership role)
A7: Exit Flag | B7: Average of WorkLifeBalance Score
A8: 0 (Non Recent and active) | B8: 2.7411765
A9: 1 (Recent) | B9: 2.8544304
A10: Grand Total | B10: 2.7957317
A12: The average Work-Life Balance score of recently exited leaders is actually slightly higher that than of those current active and non- recently exited.
A14: T-test
A15: p = | B15: =_xlfn.T.TEST(A19:A176,B19:B188,2,3) -> 0.14839901
A17: Work Life Balance Scores
A18: WLB Recent Exit | B18: WLB Non recent and active
A19: 3 | B19: 3
A20: 3 | B20: 3
A21: 4 | B21: 3
A22: 4 | B22: 2
A23: 3 | B23: 4
A24: 2 | B24: 4
A25: 3 | B25: 3
A26: 3 | B26: 3
A27: 2 | B27: 3
A28: 3 | B28: 2
A29: 3 | B29: 3
A30: 3 | B30: 3
... A176: 3 | B176: 3
B177: 3
B178: 2
B179: 2
B180: 2
B181: 3
B182: 3
B183: 2
B184: 1
B185: 3
B186: 3
B187: 3
B188: 3
A191: Findings
A192: There is no statistical signficant relationship between the work-life balance scores of leaders who exited recently and those who did not.
...

Sheet H8_EngagementDrivers
A1: H8 | J1: Copy of Clean Data for Correlation Analysis
A2: Hypothesis: Job satisfaction scores correlate with attrition & | J2: Leadership Filter 1
A3: Hypothesis: Higher satisfaction scores are associated with lower attrition among employees. | J3: Recent Exit Flag | K3: Exit Type | L3: WorkEnvironmentSatisfaction | M3: JobSatisfaction | N3: Manager Satisfaction | O3: WorkLifeBalance Score | P3: Overall Engagement Score
J4: 0 | L4: 1 | M4: 4 | N4: 4 | O4: 3 | P4: 3
A5: Engagement Driver Correlation amonst Senior Leadership Roles | J5: 0 | L5: 2 | M5: 3 | N5: 1 | O5: 3 | P5: 2.25
A6: Driver | B6: AverageScore (Recent Exits) | C6: Average Score (Non Recent Exit and active 0) | D6: Difference | E6: Correlation | J6: 0 | L6: 1 | M6: 3 | N6: 2 | O6: 3 | P6: 2.25
A7: Job Satisfaction | B7: =AVERAGEIFS(Clean_Data!AF:AF, Clean_Data!E:E, 1,Clean_Data!AC:AC, 1) -> 2.6962025 | C7: =AVERAGEIFS(Clean_Data!AF:AF, Clean_Data!E:E, 1,Clean_Data!AC:AC, 0) -> 2.7 | D7: =C7-B7 -> 0.0037974684 | E7: =CORREL(M4:M331,J4:J331) -> -0.0017602729 | J7: 0 | L7: 1 | M7: 2 | N7: 4 | O7: 2 | P7: 2.25
A8: Work Environment Satisfaction | B8: =AVERAGEIFS(Clean_Data!AE:AE, Clean_Data!E:E, 1,Clean_Data!AC:AC, 1) -> 2.7721519 | C8: =AVERAGEIFS(Clean_Data!AE:AE, Clean_Data!E:E, 1,Clean_Data!AC:AC, 0) -> 2.7705882 | D8: =C8-B8 -> -0.0015636634 | E8: =CORREL(L4:L331,J4:J331) -> 0.00070587378 | J8: 0 | L8: 2 | M8: 3 | N8: 4 | O8: 4 | P8: 3.25
A9: Manager Satisfaction | B9: =AVERAGEIFS(Clean_Data!AG:AG, Clean_Data!E:E, 1,Clean_Data!AC:AC, 1) -> 2.6708861 | C9: =AVERAGEIFS(Clean_Data!AG:AG, Clean_Data!E:E, 1,Clean_Data!AC:AC, 0) -> 2.8117647 | D9: =C9-B9 -> 0.14087863 | E9: =CORREL(N4:N331,J4:J331) -> -0.068488432 | J9: 0 | L9: 2 | M9: 3 | N9: 1 | O9: 4 | P9: 2.5
A10: Work Life Balance Score | B10: =AVERAGEIFS(Clean_Data!AH:AH, Clean_Data!E:E, 1,Clean_Data!AC:AC, 1) -> 2.8544304 | C10: =AVERAGEIFS(Clean_Data!AH:AH, Clean_Data!E:E, 1,Clean_Data!AC:AC, 0) -> 2.7411765 | D10: =C10-B10 -> -0.11325391 | E10: =CORREL(O4:O331,J4:J331) -> 0.079710298 | J10: 0 | L10: 4 | M10: 1 | N10: 4 | O10: 3 | P10: 3
A11: Overall Engagement Score | B11: =AVERAGEIFS(Clean_Data!AI:AI, Clean_Data!E:E, 1,Clean_Data!AC:AC, 1) -> 2.7484177 | C11: =AVERAGEIFS(Clean_Data!AI:AI, Clean_Data!E:E, 1,Clean_Data!AC:AC, 0) -> 2.7558824 | D11: =C11-B11 -> 0.0074646314 | E11: =CORREL(P4:P331,J4:J331) -> -0.0076825326 | J11: 0 | L11: 4 | M11: 2 | N11: 4 | O11: 3 | P11: 3.25
J12: 0 | L12: 4 | M12: 2 | N12: 1 | O12: 3 | P12: 2.5
J13: 0 | L13: 4 | M13: 3 | N13: 4 | O13: 2 | P13: 3.25
A14: Findings | J14: 0 | L14: 3 | M14: 2 | N14: 1 | O14: 3 | P14: 2.25
A15: Job Satisfaction | B15: No relationship between job satisfaction scores and recent exits | J15: 0 | L15: 3 | M15: 2 | N15: 1 | O15: 3 | P15: 2.25
A16: Work Environment Satisfaction | B16: No relationship between work environment satisfaction scores and recent exits | J16: 0 | L16: 3 | M16: 1 | N16: 4 | O16: 2 | P16: 2.5
A17: Manager Satisfaction | B17: Very weak negative relationship; higher manager satisfaction is very slightly associated with lower exits | J17: 0 | L17: 3 | M17: 4 | N17: 2 | O17: 3 | P17: 3
A18: Work Life Balance Score | B18: Weak positive relationship; higher work life balance scores are very slightly associated with exits. | J18: 0 | L18: 4 | M18: 1 | N18: 2 | O18: 1 | P18: 2
A19: Overall Engagement Score | B19: No relationship between overall engagement scores and recent exits | J19: 0 | L19: 1 | M19: 2 | N19: 1 | O19: 3 | P19: 1.75
A20: These engagement scores have very weak correlation with recent leadership attrition. | J20: 0 | L20: 2 | M20: 3 | N20: 4 | O20: 3 | P20: 3
J21: 0 | L21: 1 | M21: 4 | N21: 4 | O21: 3 | P21: 3
J22: 0 | L22: 4 | M22: 4 | N22: 3 | O22: 4 | P22: 3.75
J23: 1 | K23: Voluntary | L23: 4 | M23: 3 | N23: 2 | O23: 3 | P23: 3
J24: 0 | K24: Voluntary | L24: 1 | M24: 3 | N24: 3 | O24: 4 | P24: 2.75
J25: 0 | K25: Voluntary | L25: 1 | M25: 4 | N25: 2 | O25: 3 | P25: 2.5
J26: 1 | K26: Voluntary | L26: 2 | M26: 2 | N26: 3 | O26: 3 | P26: 2.5
J27: 1 | K27: Involuntary | L27: 4 | M27: 1 | N27: 2 | O27: 4 | P27: 2.75
J28: 1 | K28: Voluntary | L28: 1 | M28: 3 | N28: 1 | O28: 4 | P28: 2.25
J29: 1 | K29: Involuntary | L29: 1 | M29: 2 | N29: 3 | O29: 3 | P29: 2.25
J30: 1 | K30: Involuntary | L30: 4 | M30: 4 | N30: 1 | O30: 2 | P30: 2.75
J31: 0 | K31: Involuntary | L31: 3 | M31: 4 | N31: 4 | O31: 4 | P31: 3.75
J32: 0 | K32: Voluntary | L32: 1 | M32: 3 | N32: 3 | O32: 3 | P32: 2.5
J33: 0 | K33: Involuntary | L33: 2 | M33: 2 | N33: 4 | O33: 3 | P33: 2.75
J34: 0 | K34: Involuntary | L34: 4 | M34: 1 | N34: 2 | O34: 2 | P34: 2.25
... J331: 1 | K331: Involuntary | L331: 2 | M331: 3 | N331: 2 | O331: 3 | P331: 2.5

Sheet H9_SalaryIncrease
A1: H9
A2: Hypothesis: Smaller salary increases are associated with higher leadership attrition.
A4: Average Salary Percent Increase
A5: Recent Exit Leaders (1) | B5: =AVERAGEIFS(Clean_Data!I2:I1472, Clean_Data!E2:E1472,1,Clean_Data!AC2:AC1472, 1) -> 0.15297468
A6: Non Recent Exit & active leaders (0) | B6: =AVERAGEIFS(Clean_Data!I2:I1472, Clean_Data!E2:E1472,1,Clean_Data!AC2:AC1472, 0) -> 0.15311765
A8: Findings
A9: Leadership employees who exited recently did not receive smaller salary increases.
A11: T-test
A12: p = | B12: =_xlfn.T.TEST(A16:A173,B16:B185,2,3) -> 0.97300191
A14: Salary Percent Increase
A15: Recent Exit Leaders (1) | B15: Non Recent Exit Leaders (0)
A16: 0.21 | B16: 0.15
A17: 0.13 | B17: 0.13
A18: 0.14 | B18: 0.11
A19: 0.13 | B19: 0.12
A20: 0.15 | B20: 0.12
A21: 0.11 | B21: 0.19
A22: 0.13 | B22: 0.13
A23: 0.17 | B23: 0.12
A24: 0.17 | B24: 0.14
A25: 0.14 | B25: 0.15
A26: 0.14 | B26: 0.11
A27: 0.12 | B27: 0.11
... A173: 0.22 | B173: 0.22
B174: 0.18
B175: 0.12
B176: 0.14
B177: 0.11
B178: 0.14
B179: 0.13
B180: 0.11
B181: 0.11
B182: 0.11
B183: 0.19
B184: 0.2
B185: 0.13
A188: Findings
A189: There is no statistically signifcant difference in salary increases between leaders who exited recently and those who did not.
A190: Pay increase does not appear to be a meaningful attrition driver in this data set.

Sheet H10_Performance
A1: H10
A2: Hypothesis: Lower performance ratings are associated with higher leadership attrition.
A4: Average Performance Rating Score
A5: Recent Exit Leaders (1) | B5: =AVERAGEIFS(Clean_Data!S2:S1472, Clean_Data!E2:E1472, 1, Clean_Data!AC2:AC1472, 1) -> 3.1772152
A6: Non Recent Exit & active leaders (0) | B6: =AVERAGEIFS(Clean_Data!S2:S1472, Clean_Data!E2:E1472, 1, Clean_Data!AC2:AC1472, 0) -> 3.1647059
A8: Findings
A9: Employees who exited recently were not lower performers. However, 0.02 difference is very small so there is no meaningful difference.
A12: T-test
A13: p = | B13: =_xlfn.T.TEST(A17:A174,B17:B186,2,3) -> 0.76463937
A15: Performance Rating
A16: Recent Exit Leaders | B16: Non Recent Exit Leaders
A17: 4 | B17: 3
A18: 3 | B18: 3
A19: 3 | B19: 3
A20: 3 | B20: 3
A21: 3 | B21: 3
A22: 3 | B22: 3
A23: 3 | B23: 3
A24: 3 | B24: 3
A25: 3 | B25: 3
A26: 3 | B26: 3
A27: 3 | B27: 3
A28: 3 | B28: 3
... A174: 4 | B174: 4
B175: 3
B176: 3
B177: 3
B178: 3
B179: 3
B180: 3
B181: 3
B182: 3
B183: 3
B184: 3
B185: 4
B186: 3
A189: Findings
A190: The difference in performance ratings between recent exit leaders and non recent exit leaders was not statistically significant.

Sheet Summary_Findings
A1: Summary of Findings
A3: Hypothesis | B3: Variable Tested | C3: Statistical Method | D3: Result | E3: Supported
A4: H1 | B4: Tenure stage | C4: Pivot table-descriptive statistics | D4: Attrition rates differed by tenure stage (early tenure highest attrition, long tenure lowest attrition rate) | E4: Partial
A5: H2 | B5: Long tenure | C5: chi square | D5: p=0.12 | E5: No
A6: H3 | B6: Department | C6: chi square | D6: p=0.42 | E6: No
A7: H4 | B7: Years in Current Role | C7: t-test | D7: p=0.65 | E7: No
A8: H5 | B8: Department | C8: Pivot table-descriptive statistics | D8: Sales and R&D experience higher attrition than leaders in other areas | E8: Yes
A9: H6 | B9: Travel Requirements | C9: chi square | D9: p=0.30 | E9: No
A10: H7 | B10: Work Life Balance | C10: t-test | D10: p=0.15 | E10: No
A11: H8 | B11: Engagement Drivers | C11: correlation | D11: Weak Correlation (-0.07-0.08) | E11: No
A12: H9 | B12: Salary Increase | C12: t-test | D12: p=0.97 | E12: No
A13: H10 | B13: Performance Rating | C13: t-test | D13: Similar averages (3.8 vs 3.16) and p=0.76 | E13: No

Sheet External Data
A1: Metric | B1: Benchmark Value | C1: Source
A2: Average leadership turnover rate | B2: 8-12% annually | C2: industry HR research
A3: Cost of replacing a senior leader | B3: 1.5-2x annual salary | C3: academic research
A4: Mid-tenure turnover risk | B4: highest mobility around 3-5 years | C4: workforce mobility studies
A5: work-life balance impact on retention | B5: strong predictor of turnover | C5: employee engagement research

Sheet Employee Engagement Survey
A1: EmployeeNumber | B1: WorkEnvironmentSatisfaction | C1: JobSatisfaction | D1: Manager Satisfaction | E1: WorkLifeBalance Score
A2: 701 | B2: 4 | C2: 3 | D2: 4 | E2: 3
A3: 1012 | B3: 2 | C3: 4 | D3: 4 | E3: 3
A4: 1056 | B4: 4 | C4: 2 | D4: 2 | E4: 3
A5: 1876 | B5: 2 | C5: 4 | D5: 3 | E5: 2
A6: 1928 | B6: 3 | C6: 1 | D6: 4 | E6: 3
A7: 243 | B7: 2 | C7: 4 | D7: 3 | E7: 2
A8: 1273 | B8: 3 | C8: 4 | D8: 4 | E8: 3
A9: 1974 | B9: 4 | C9: 4 | D9: 3 | E9: 3
A10: 411 | B10: 4 | C10: 3 | D10: 1 | E10: 3
A11: 1270 | B11: 4 | C11: 3 | D11: 4 | E11: 3
A12: 30 | B12: 3 | C12: 4 | D12: 4 | E12: 3
A13: 1433 | B13: 1 | C13: 2 | D13: 3 | E13: 4
